Workbook
Name A_ApplianceStarRating: [1]V5ToolData!$BP$5:$BP$20
Name A_ApplianceStarRatingEnergy: [1]V5ToolData!$BP$6:$BV$20
Name A_DHWTankSelection: [1]!A_DHWTank[[#All],[DHWTank]]
Name A_DHWTankSelection: [1]!A_DHWTank[[#All],[DHWTank]]
Name A_EastWestWallLength: [1]V5Calc!$D$27
Name A_EquatorialWallLength: [1]V5Calc!$D$26
Name A_Occupancy: [1]Verification!$F$29
Name A_RefBldg: [1]Variants!$D$752
Name A_RefBldgAirtightness: [1]Variants!$D$754
Name A_RefBldgWallAreas: [1]Areas!$V$136:$V$139
Name A_RefBldgWindowVent: [1]Variants!$D$755
Name A_SimpleModel: [1]Summary!$H$66
Name A_TFA: [1]Summary!$K$59
Name AdjacentBC: [1]!A_AdjacentBC[AdjacentBC]
Name AdjacentBC: [1]!A_AdjacentBC[AdjacentBC]
Name Are_Urinals_installed?: #REF!
Name Are_Urinals_installed?: #REF!
Name Are_Urinals_installed?: #REF!
Name Are_Urinals_installed?: #REF!
Name checklist: Data!$A$195:$A$197
Name Daten_BHKW_Faktoren: Data!#REF!
Name Daten_BHKW_Name: Data!#REF!
Name Daten_CO2_Faktoren_Eigene_Eingabe: Data!#REF!
Name Daten_Eigene_Energietraeger_Faktoren: Data!#REF!
Name Daten_Eigene_Energietraeger_Namen: Data!#REF!
Name Daten_PE_Faktoren_Eigene_Eingabe: Data!#REF!
Name DuctedElectricHeatPump: #REF!
Name DuctedElectricHeatPump: #REF!
Name DuctedElectricHeatPump: #REF!
Name DuctedElectricHeatPump: #REF!
Name DuctedElectricHeatPumpGeneric: #REF!
Name DuctedElectricHeatPumpGeneric: #REF!
Name DuctedElectricHeatPumpGeneric: #REF!
Name ECCHO_vent: Data!#REF!
Name ElectricResistive: #REF!
Name ElectricResistive: #REF!
Name ElectricResistive: #REF!
Name ElectricResistiveGeneric: #REF!
Name ElectricResistiveGeneric: #REF!
Name ElectricResistiveGeneric: #REF!
Name ElectricUnderfloorHeating: #REF!
Name ElectricUnderfloorHeating: #REF!
Name ElectricUnderfloorHeating: #REF!
Name ElectricUnderfloorHeatingGeneric: #REF!
Name Ene1_headingsEC: '[2]Ecology Calculator'!$B$5,'[2]Ecology Calculator'!$B$7,'[2]Ecology Calculator'!$B$9:$F$10,'[2]Ecology Calculator'!$B$11:$B$31,'[2]Ecology Calculator'!$D$28:$F$31
Name Enecon_headingsEC: '[2]Ecology Calculator'!$B$5,'[2]Ecology Calculator'!$B$7,'[2]Ecology Calculator'!$B$9:$F$10,'[2]Ecology Calculator'!$B$11:$B$31,'[2]Ecology Calculator'!$D$28:$F$31
Name equipment: #REF!
Name Erdreich_Gebaeudedaten_Flaeche_Bodenplatte: [1]Ground!$H$18
Name Erdreich_Gebaeudedaten_Flaeche_Bodenplatte2: [1]Ground!$AB$18
Name Fenster_Auslegungstemperatur_Eigene_Eingabe: [1]Windows!$BR$17
Name Fernwaerme_Nutzungsgrad_Waermeuebergabestation: '[1]District heating'!$Q$38
Name Fernwaerme_Waermequelle: '[1]District heating'!$N$21
Name Fields: #REF!,#REF!,#REF!,#REF!,#REF!,#REF!,#REF!,#REF!
Name Fields: #REF!,#REF!,#REF!,#REF!,#REF!,#REF!,#REF!,#REF!
Name Fields: #REF!,#REF!,#REF!,#REF!,#REF!,#REF!,#REF!,#REF!
Name Flaechen_Flaecheneingabe_U_Wert_Aussentuer: [1]Areas!$AE$40
Name Headings: #REF!,#REF!,#REF!,#REF!,#REF!
Name Headings: #REF!,#REF!,#REF!,#REF!,#REF!
Name Headings: #REF!,#REF!,#REF!,#REF!,#REF!
Name Headings2: '[3]Transport Calculator'!$B$5:$B$11,'[3]Transport Calculator'!$C$5:$D$7,'[3]Transport Calculator'!$B$14:$B$20,'[3]Transport Calculator'!$C$14:$D$16,'[3]Transport Calculator'!$C$22:$D$22

Sheet Summary
C10: Calculation Tool | D10: HSTT12
C11: For resource efficiency, water use, site water and ecology, natural lighting, healthy materials and sustainble materials
C14: General details
C15: Building Type
C16: Territorial Authority
C17: H1 Climate Zone (4th Edition) | D17: =VLOOKUP($D$16,HS_Location_Master,6, FALSE) -> #N/A
C18: H1 Climate Zone (5th Edition) | D18: =VLOOKUP($D$16,HS_Location_Master,9, FALSE) -> #N/A
C19: Overheating Region | D19: =VLOOKUP($D$16,HS_Location_Master,5, FALSE) -> #N/A
C20: Water Region | D20: =VLOOKUP($D$16,HS_Location_Master,7, FALSE) -> #N/A
C21: Total building footprint of project (m2) | E21: Only required if EN5 points are claimed
C22: Total conditioned area of the dwelling (m2)
C23: Number of Bedrooms in dwelling (0 if studio) | E23: Please enter 0 for studio
C28: Points Summary | D28: Each of the calculator tabs will show a detailed breakdown of where points were achieved
C29: Efficient
C30: EF1 Resource Efficiency | D30: =IFERROR(DRE!$P$8,0) -> 4
C31: EF2 Urban Density | D31: =DRE!P9 -> 0
C32: EF3 Water use | D32: ='Water Calculator'!$F$6+'Water Calculator'!$F$7 -> 0
C35: Healthy and Comfortable
C36: HC5 Natural light | D36: ='Natural Light Calculator'!$D$7 -> 0
C37: HC7 Healthy materials | D37: ='Materials Calculator'!H9 -> 0
C40: Environmentally Responsible
C41: EN3 Sustainable materials | D41: ='Materials Calculator'!D9 -> 0
C42: EN5 Site water and ecology | D42: ='Water Calculator'!$F$8+'Water Calculator'!$F$9+'Water Calculator'!$F$10+'Water Calculator'!$F$11 -> 0 | G42: Release version
G43: 45642 | H43: v5_1_5 update

Sheet Overheating
C2: Risk Based review to Overheating
C4: Checklist of factors to highlight weather full dynamic simulation is recommended
C5: Overheating is likely to be present in dwellings with large glazing areas, in a city, minimal shading, north facing windows, single aspect, or limited opening windows.
C7: Overall risk factor | D7: =IF(COUNTIF(E14:L33,"-")>=1,"Please fill in all cells",CONCATENATE(Data!$A$60,"/",54)) -> Please fill in all cells
C9: =IF(D7="Please fill in all cells","",CONCATENATE(IF(Data!A60>=Data!A63,Data!B63,""),IF(AND(Data!A60>Data!A65,Data!A60<Data!A63),Data!B64,""),IF(Data!A60<=Data!A65,Data!B65,"")))
C12: Exacerbation Factors - Increase the risk of overheating occurring | J12: Mitigation Factors - Reduce the risk of overheating occurring
B14: Site Measures | C14: Factor One: | D14: Where in New Zealand is the site? | E14: =IF(Summary!D19="","-",Summary!D19) -> #N/A | F14: =VLOOKUP(E14,LocationTable,16,FALSE) -> #N/A | J14: Factor Eight: | K14: Is the dwelling shaded from surrounding buildings or foliage within a distance equivalent to the height? | L14: - | M14: =VLOOKUP(L14,Data!$A$4:$B$61,2,FALSE) -> n/a
C15: Site location | F15: =IFERROR((IF(F14="Low risk",Data!$A$68,0)+IF(F14="Medium risk",Data!$A$69,0)+IF(F14="High risk",Data!$A$70,0))*RIGHT(G15,1),0) -> 0 | G15: X3 | J15: Site shading | M15: =IFERROR((IF(M14="Low risk",Data!$A$68,0)+IF(M14="Medium risk",Data!$A$69,0)+IF(M14="High risk",Data!$A$70,0))*RIGHT(N15,1),0) -> 0 | N15: X1
C17: Factor Two | D17: Is the dwellings site rural, suburban, or in a city? | E17: - | F17: =VLOOKUP(E17,Data!$A$4:$B$61,2,FALSE) -> n/a | J17: Factor Nine: | K17: What level of shading does the eves or shading device provide? | L17: - | M17: =VLOOKUP(L17,Data!$A$4:$B$61,2,FALSE) -> n/a
C18: Urban heat island | F18: =IFERROR((IF(F17="Low risk",Data!$A$68,0)+IF(F17="Medium risk",Data!$A$69,0)+IF(F17="High risk",Data!$A$70,0))*RIGHT(G18,1),0) -> 0 | G18: X1 | J18: External shading | M18: =IFERROR((IF(M17="Low risk",Data!$A$69,0)+IF(M17="Medium risk",Data!$A$68,0)+IF(M17="High risk",Data!$A$68,0))*RIGHT(N18,1),0) -> 0 | N18: X2
C20: Factor Three: | D20: How many of the following are barriers to opening windows? Noise level, Poor air quality, Security. | E20: - | F20: =VLOOKUP(E20,Data!$A$4:$B$61,2,FALSE) -> n/a | J20: Factor Ten: | K20: Is the dwelling constructed out of high mass materials with a quiet and secure method to ventilate at night? | L20: - | M20: =VLOOKUP(L20,Data!$A$4:$B$61,2,FALSE) -> n/a
C21: Open window period | F21: =IFERROR((IF(F20="Low risk",Data!$A$68,0)+IF(F20="Medium risk",Data!$A$69,0)+IF(F20="High risk",Data!$A$70,0))*RIGHT(G21,1),0) -> 0 | G21: X3 | J21: Thermal mass | M21: =IFERROR((IF(M20="Low risk",Data!$A$70,0)+IF(M20="Medium risk",Data!$A$69,0)+IF(M20="High risk",Data!$A$68,0))*RIGHT(N21,1),0) -> 0 | N21: X1
B23: Passive Measures | C23: Factor Four: | D23: What is the typology of the dwelling? | E23: - | F23: =VLOOKUP(E23,Data!$A$4:$B$61,2,FALSE) -> n/a | J23: Factor Eleven: | K23: Are windows able to fully open? | L23: - | M23: =VLOOKUP(L23,Data!$A$4:$B$61,2,FALSE) -> n/a
C24: External heat loss | F24: =IFERROR((IF(F23="Low risk",Data!$A$68,0)+IF(F23="Medium risk",Data!$A$69,0)+IF(F23="High risk",Data!$A$70,0))*RIGHT(G24,1),0) -> 0 | G24: X2 | J24: Openable window | M24: =IFERROR((IF(M23="Low risk",Data!$A$68,0)+IF(M23="Medium risk",Data!$A$69,0)+IF(M23="High risk",Data!$A$70,0))*RIGHT(N24,1),0) -> 0 | N24: X2
C26: Factor Five: | D26: Percentage of window area to total floor area. | E26: - | F26: =VLOOKUP(E26,Data!$A$4:$B$61,2,FALSE) -> n/a | J26: Factor Twelve: | K26: Is there a form of continuous mechanical ventilation? | L26: - | M26: =VLOOKUP(L26,Data!$A$4:$B$61,2,FALSE) -> n/a
C27: Glazing | F27: =IFERROR((IF(F26="Low risk",Data!$A$68,0)+IF(F26="Medium risk",Data!$A$69,0)+IF(F26="High risk",Data!$A$70,0))*RIGHT(G27,1),0) -> 0 | G27: X4 | J27: Mechanical ventilation | M27: =IFERROR((IF(M26="Low risk",Data!$A$68,0)+IF(M26="Medium risk",Data!$A$69,0)+IF(M26="High risk",Data!$A$70,0))*RIGHT(N27,1),0) -> 0 | N27: X1
C29: Factor Six: | D29: Is there an unobstructed path for airflow through the dwelling? | E29: - | F29: =VLOOKUP(E29,Data!$A$4:$B$61,2,FALSE) -> n/a | L29: Subtotal | M29: =SUM(M14:M27) -> 0
C30: Natural ventilation | F30: =IFERROR((IF(F29="Low risk",Data!$A$68,0)+IF(F29="Medium risk",Data!$A$69,0)+IF(F29="High risk",Data!$A$70,0))*RIGHT(G30,1),0) -> 0 | G30: X2
C32: Factor Seven: | D32: What direction do most bedroom windows face? | E32: - | F32: =VLOOKUP(E32,Data!$A$4:$B$61,2,FALSE) -> n/a
C33: Orientation | F33: =IFERROR((IF(F32="Low risk",Data!$A$68,0)+IF(F32="Medium risk",Data!$A$69,0)+IF(F32="High risk",Data!$A$70,0))*RIGHT(G33,1),0) -> 0 | G33: X3
E35: Subtotal | F35: =SUM(F14:F33) -> #N/A

Sheet Water Calculator
D5: Total Points
D6: EF3 | E6: Water efficiency | F6: =E162 -> 0
E7: Rainwater | F7: =IFERROR(IF(D35="yes",IF($D$92="Apartment",$M$158,$I$158),0),0) -> 0
D8: EN5 | E8: Brownfield | F8: =IF(P106,0.5,0) -> 0
E9: Stormwater | F9: =E190 -> 0
E10: Native Planting | F10: =J190 -> 0
E11: WSUD | F11: =IF(P107,1,0) -> 0 | K11: Flow Rates and WELS Ratings Table
K13: Fixture | L13: WELS Rating | M13: Max Flow
C14: Part A: EF3 Gross indoor individual water use | K14: Shower | L14: 1 | M14: 16 | N14: (L/min)
C15: Indoor water use summary - Enter tested flow rates or check WELS rating labels | G15: Use L/person | H15: Use % | L15: 2 | M15: 12 | N15: (L/min)
C16: Worst case shower (L/min) | G16: =IF(D16="",12,D16)*6.21*IF(G20>0,4.37/5.6,1) -> 74.52 | H16: =G16/$G$27 -> 0.45245902 | I16: Mandatory | L16: 3 | M16: 9 | N16: (L/min)
C17: Toilet (L Full Flush / L Half Flush ) | E17: / | G17: =IF(AND(D17="",F17=""),(6+(3*4)),IF(D17+F17=D17,D17*5,(4*F17)+D17)) -> 18 | H17: =G17/$G$27 -> 0.10928962 | I17: Mandatory | L17: 3* | M17: 7.5 | N17: (L/min)
C18: Worst case kitchen and laundry tap (L/min) | G18: =(IF(D18="",12,D18)*0.44)+10.36 -> 15.64 | H18: =G18/$G$27 -> 0.094960534 | I18: Optional | K18: Tapware | L18: 4 | M18: 7.5 | N18: (L/min)
C19: Worst case basin tap (L/min) | G19: =(IF(D19="",12,D19)*1.58)+1.58 -> 20.54 | H19: =G19/$G$27 -> 0.1247116 | I19: Optional | L19: 5 | M19: 6 | N19: (L/min)
C20: Bath (if present) - Capacity to Overflow (L) | G20: =D20*0.11 -> 0 | H20: =G20/$G$27 -> 0 | I20: Optional | L20: 6 | M20: 4.5 | N20: (L/min)
C21: Dish washer (L/ Cycle) / Number of place settings | E21: / | G21: =IFERROR(IF(D21/F21=0,1.25,D21/F21),1.25)*3.6 -> 4.5 | H21: =G21/$G$27 -> 0.027322404 | I21: Optional | K21: Toilet | L21: 3 | M21: 6/3 | N21: (L/flush) Full/Half
C22: Washing machine (L/ Cycle) / Load capacity (Kg) | E22: / | G22: =IFERROR(IF(D22/F22=0,15,D22/F22),15)*2.1 -> 31.5 | H22: =G22/$G$27 -> 0.19125683 | I22: Optional | L22: 4 | M22: 4.5/3 | N22: (L/flush) Full/Half
C23: Waste disposal unit (Insinkerator) - present? | D23: no | G23: =IF(D23="yes",3.08,0) -> 0 | H23: =G23/$G$27 -> 0 | I23: Optional | L23: 4.5 | M23: 2.5 | N23: (L/flush)
C24: Note: If residents HAVE access to a shared communal laundry within the development but NO laundry facilities at home, then enter washing machine fields above. In this case, use the least water efficient washing machine in the communal laundry nearest to the dwelling. Otherwise leave these blank. Also note: for washer dryers, enter the total water use (washing + drying). | K24: *Showers that have a flow rate of 7.5 L/min or less are still labelled 3 star.
C26: Expected Occupancy | D26: =IFERROR(VLOOKUP(H95,F91:H94,3,FALSE),H92) -> 1.0120645
D27: Unadjusted daily indoor use (L) per Person | G27: =SUM(G16:G23) -> 164.7 | H27: Nominal 180 - 190 L/p/day
C29: Is the dwelling individually metered AND billed on usage? | D29: TRUE | E29: =IF(D29,"Homestar assumes a further 5% reduction in consumption with metered billing","") -> Homestar assumes a further 5% reduction in consumption with metered billing | G29: Check if dwelling is metered individually
D30: Total daily indoor water use (L) per Person | G30: =IF(P100,G27*0.95,G27) -> 164.7
C33: Part B: EF3 Demand offset through rainwater harvesting, and EN5 Site water and ecology (water tanks) | K33: This is a problem if we use the ECCHO model for occupancy (maybe) current way of apportioning is based on occupancy (occupancy a dwelling of this typology, vs total occupany across all units connected to the system. If we move to KO model it’s a multiplication of total bedrooms by 2, so its ok. but, if its the eccho model it gets complicated. My feeling would be we'd either just use the total number of bedrooms directly (apportion fraction = bedrooms of unit/total beds across all units), or CFA of unit/ CFA across all units. The latter option requires additional inputs so I've gone with the former. I think this is reasonable, as while we don't use CFA directly, number of bedrooms is a general proxy for how big one house is compared to another, given lanning regulations around minimum bedroom sizes
C34: Rain Water System - Complete Part A above first before this section
C35: Does the dwelling have rainwater collection?
C37: Total number of dwellings / bedrooms in dwelling(s) connected to rainwater tank (# Dwellings / # Bedrooms) | E37: /
C38: Rain water tank size (L) (only include capacity below overflow for combined rainwater and stormwater systems)
C39: Apportioned Tank Size (L) | D39: =IF(OR(F37=0,F37=D95),D38,IFERROR(VLOOKUP(H95,F91:I94,4,FALSE),D38)) -> 0
C40: Roof catchment area (m2) (for rain water harvesting and stormwater)
C41: Roof Type (for run off coefficient calculation)
C42: Roof Slope - Enter EITHER % slope (rise/run) OR angle (degrees) and select which | E42: slope or angle?
C43: Calculated Run off co-efficient | D43: =IFERROR(VLOOKUP(D41,K101:L102,2,FALSE)+IF(L111<=5%,-0.05,IF(L111<=10%,0,IF(L111<=20%,0.05,0.1))),0) -> 0
C45: Please select the elements that the rainwater tank is connected to:
C46: Outdoor (and common areas in apartments)
C47: Washing machine (Note that laundry tubs must be on potable water supply for safety)
C48: Toilet flushing
C49: Dishwasher
C52: Apartments only
C53: Monthly average common area water use (L) | E53: Optional, to be used in case there is a TQ
...

Sheet Natural Light Calculator
AN1: Hide Everything to Right | AP1: hide
B2: Natural Light Calculator | AV2: Glazed Area | AW2: Surface Area | AX2: Wall Area | AY2: Floor Area | AZ2: Ceiling Area | BA2: Average Reflectance | BB2: Sun Angle
AQ3: H | AR3: D | AS3: Hw/2 | AT3: Angle a | AU3: Angle b
AP4: =C20 -> Main Bedroom | AQ4: =IF(N45-AQ26-P45>0,N45-AQ26-P45,0) -> 0 | AR4: =M45 -> 0 | AS4: =IF($U45>=1,VLOOKUP($T45,$J$15:$N$34,3,FALSE)/2,$Q45/2) -> 0 | AT4: =IF(AND(M45=0,N45=0),0,DEGREES(ASIN(AQ4/(SQRT((AQ4^2)+(AR4^2)))))) -> 0 | AU4: =DEGREES(ASIN(O45/(SQRT((O45^2)+(AS4^2))))) -> #DIV/0! | AV4: =(IF(T46="",0,VLOOKUP($T46,$J$15:$N$34,5,FALSE)*U46))+(IF(T45="",0,(VLOOKUP($T45,$J$15:$N$34,5,FALSE)*U45)))+(IF(T47="",0,VLOOKUP($T47,$J$15:$N$34,5,FALSE)*U47))+(Q45*R45)+(Q46*R46)+(Q47*R47) -> 0 | AW4: =AX4+AY4+AZ4 -> 0 | AX4: =(2*((IF($D$13>0,$D$13,D20)*F20)+(IF($D$13>0,$D$13,D20)*E20)))-AV4 -> 0 | AY4: =E20*F20 -> 0 | AZ4: =AY4 -> 0 | BA4: =((AZ4*VLOOKUP(H20,$BG$4:$BJ$6,2,FALSE))/AW4)+((AX4*VLOOKUP(H20,$BG$4:$BJ$6,3,FALSE))/AW4)+((AY4*VLOOKUP(H20,$BG$4:$BJ$6,4,FALSE))/AW4) -> #N/A | BB4: =90-AT4-AU4 -> #DIV/0! | BC4: =IF(K15="","",J15) -> Window 1 | BE4: Living Room One | BF4: 0.015 | BG4: Medium | BH4: 0.7 | BI4: 0.4
AP5: =C21 -> Bedroom Two | AQ5: =IF(N48-AQ27-P48>0,N48-AQ27-P48,0) -> 0 | AR5: =M48 -> 0 | AS5: =IF($U48>=1,VLOOKUP($T48,$J$15:$N$34,3,FALSE)/2,$Q48/2) -> 0 | AT5: =IF(AND(M48=0,N48=0),0,DEGREES(ASIN(AQ5/(SQRT((AQ5^2)+(AR5^2)))))) -> 0 | AU5: =DEGREES(ASIN(O48/(SQRT((O48^2)+(AS5^2))))) -> #DIV/0! | AV5: =(IF(T49="",0,VLOOKUP($T49,$J$15:$N$34,5,FALSE)*U49))+(IF(T48="",0,(VLOOKUP($T48,$J$15:$N$34,5,FALSE)*U48)))+(Q48*R48)+(Q49*R49) -> 0 | AW5: =AX5+AY5+AZ5 -> 0 | AX5: =(2*((IF($D$13>0,$D$13,D21)*F21)+(IF($D$13>0,$D$13,D21)*E21)))-AV5 -> 0 | AY5: =E21*F21 -> 0 | AZ5: =AY5 -> 0 | BA5: =((AZ5*VLOOKUP(H21,$BG$4:$BJ$6,2,FALSE))/AW5)+((AX5*VLOOKUP(H21,$BG$4:$BJ$6,3,FALSE))/AW5)+((AY5*VLOOKUP(H21,$BG$4:$BJ$6,4,FALSE))/AW5) -> #N/A | BB5: =90-AT5-AU5 -> #DIV/0! | BC5: =IF(K16="","",J16) -> Window 2 | BE5: Living Room Two | BF5: 0.015 | BG5: High | BH5: 0.7 | BI5: 0.6
C6: Total Points HC - 5 | AP6: =C22 -> - | AQ6: =IF(N50-AQ28-P50>0,N50-AQ28-P50,0) -> 0 | AR6: =M50 -> 0 | AS6: =IF($U50>=1,VLOOKUP($T50,$J$15:$N$34,3,FALSE)/2,$Q50/2) -> 0 | AT6: =IF(AND(M50=0,N50=0),0,DEGREES(ASIN(AQ6/(SQRT((AQ6^2)+(AR6^2)))))) -> 0 | AU6: =DEGREES(ASIN(O50/(SQRT((O50^2)+(AS6^2))))) -> #DIV/0! | AV6: =(IF(T51="",0,VLOOKUP($T51,$J$15:$N$34,5,FALSE)*U51))+(IF(T50="",0,(VLOOKUP($T50,$J$15:$N$34,5,FALSE)*U50)))+(Q50*R50)+(Q51*R51) -> 0 | AW6: =AX6+AY6+AZ6 -> 0 | AX6: =(2*((IF($D$13>0,$D$13,D22)*F22)+(IF($D$13>0,$D$13,D22)*E22)))-AV6 -> 0 | AY6: =E22*F22 -> 0 | AZ6: =AY6 -> 0 | BA6: =((AZ6*VLOOKUP(H22,$BG$4:$BJ$6,2,FALSE))/AW6)+((AX6*VLOOKUP(H22,$BG$4:$BJ$6,3,FALSE))/AW6)+((AY6*VLOOKUP(H22,$BG$4:$BJ$6,4,FALSE))/AW6) -> #N/A | BB6: =90-AT6-AU6 -> #DIV/0! | BC6: =IF(K17="","",J17) | BE6: Kitchen One | BF6: 0.02
C7: Natural Light | D7: =IF(CONCATENATE(IF(AND(G13=BK4,G14=BM4),AW24,""),IF(AND(G13=BK5,G14=BM4),SUM(AX24:AY24),""),IF(AND(G13=BK6,G14=BM4),SUM(AZ24:BB24),""),IF(AND(G13=BK4,G14=BM5),BD24,""),IF(AND(G13=BK5,G14=BM5),SUM(BE24:BF24),""),IF(AND(G13=BK6,G14=BM5),SUM(BG24:BI24),""))="",0,CONCATENATE(IF(AND(G13=BK4,G14=BM4),AW24,""),IF(AND(G13=BK5,G14=BM4),SUM(AX24:AY24),""),IF(AND(G13=BK6,G14=BM4),SUM(AZ24:BB24),""),IF(AND(G13=BK4,G14=BM5),BD24,""),IF(AND(G13=BK5,G14=BM5),SUM(BE24:BF24),""),IF(AND(G13=BK6,G14=BM5),SUM(BG24:BI24),""))) -> 0 | AP7: =C23 -> - | AQ7: =IF(N52-AQ29-P52>0,N52-AQ29-P52,0) -> 0 | AR7: =M52 -> 0 | AS7: =IF($U52>=1,VLOOKUP($T52,$J$15:$N$34,3,FALSE)/2,$Q52/2) -> 0 | AT7: =IF(AND(M52=0,N52=0),0,DEGREES(ASIN(AQ7/(SQRT((AQ7^2)+(AR7^2)))))) -> 0 | AU7: =DEGREES(ASIN(O52/(SQRT((O52^2)+(AS7^2))))) -> #DIV/0! | AV7: =(IF(T53="",0,VLOOKUP($T53,$J$15:$N$34,5,FALSE)*U53))+(IF(T52="",0,(VLOOKUP($T52,$J$15:$N$34,5,FALSE)*U52)))+(Q52*R52)+(Q53*R53) -> 0 | AW7: =AX7+AY7+AZ7 -> 0 | AX7: =(2*((IF($D$13>0,$D$13,D23)*F23)+(IF($D$13>0,$D$13,D23)*E23)))-AV7 -> 0 | AY7: =E23*F23 -> 0 | AZ7: =AY7 -> 0 | BA7: =((AZ7*VLOOKUP(H23,$BG$4:$BJ$6,2,FALSE))/AW7)+((AX7*VLOOKUP(H23,$BG$4:$BJ$6,3,FALSE))/AW7)+((AY7*VLOOKUP(H23,$BG$4:$BJ$6,4,FALSE))/AW7) -> #N/A | BB7: =90-AT7-AU7 -> #DIV/0! | BC7: =IF(K18="","",J18) | BE7: Kitchen Two | BF7: 0.02
AP8: =C24 -> - | AQ8: =IF(N54-AQ30-P54>0,N54-AQ30-P54,0) -> 0 | AR8: =M54 -> 0 | AS8: =IF($U54>=1,VLOOKUP($T54,$J$15:$N$34,3,FALSE)/2,$Q54/2) -> 0 | AT8: =IF(AND(M54=0,N54=0),0,DEGREES(ASIN(AQ8/(SQRT((AQ8^2)+(AR8^2)))))) -> 0 | AU8: =DEGREES(ASIN(O54/(SQRT((O54^2)+(AS8^2))))) -> #DIV/0! | AV8: =(IF(T55="",0,VLOOKUP($T55,$J$15:$N$34,5,FALSE)*U55))+(IF(T54="",0,(VLOOKUP($T54,$J$15:$N$34,5,FALSE)*U54)))+(Q54*R54)+(Q55*R55) -> 0 | AW8: =AX8+AY8+AZ8 -> 0 | AX8: =(2*((IF($D$13>0,$D$13,D24)*F24)+(IF($D$13>0,$D$13,D24)*E24)))-AV8 -> 0 | AY8: =E24*F24 -> 0 | AZ8: =AY8 -> 0 | BA8: =((AZ8*VLOOKUP(H24,$BG$4:$BJ$6,2,FALSE))/AW8)+((AX8*VLOOKUP(H24,$BG$4:$BJ$6,3,FALSE))/AW8)+((AY8*VLOOKUP(H24,$BG$4:$BJ$6,4,FALSE))/AW8) -> #N/A | BB8: =90-AT8-AU8 -> #DIV/0! | BC8: =IF(K19="","",J19) | BE8: Main Bedroom | BF8: 0.015
AP9: =C25 -> - | AQ9: =IF(N56-AQ31-P56>0,N56-AQ31-P56,0) -> 0 | AR9: =M56 -> 0 | AS9: =IF($U56>=1,VLOOKUP($T56,$J$15:$N$34,3,FALSE)/2,$Q56/2) -> 0 | AT9: =IF(AND(M56=0,N56=0),0,DEGREES(ASIN(AQ9/(SQRT((AQ9^2)+(AR9^2)))))) -> 0 | AU9: =DEGREES(ASIN(O56/(SQRT((O56^2)+(AS9^2))))) -> #DIV/0! | AV9: =(IF(T57="",0,VLOOKUP($T57,$J$15:$N$34,5,FALSE)*U57))+(IF(T56="",0,(VLOOKUP($T56,$J$15:$N$34,5,FALSE)*U56)))+(Q56*R56)+(Q57*R57) -> 0 | AW9: =AX9+AY9+AZ9 -> 0 | AX9: =(2*((IF($D$13>0,$D$13,D25)*F25)+(IF($D$13>0,$D$13,D25)*E25)))-AV9 -> 0 | AY9: =E25*F25 -> 0 | AZ9: =AY9 -> 0 | BA9: =((AZ9*VLOOKUP(H25,$BG$4:$BJ$6,2,FALSE))/AW9)+((AX9*VLOOKUP(H25,$BG$4:$BJ$6,3,FALSE))/AW9)+((AY9*VLOOKUP(H25,$BG$4:$BJ$6,4,FALSE))/AW9) -> #N/A | BB9: =90-AT9-AU9 -> #DIV/0! | BC9: =IF(K20="","",J20) | BE9: Bedroom Two | BF9: 0.015
C10: Schedule Information | AP10: =C26 -> - | AQ10: =IF(N58-AQ32-P58>0,N58-AQ32-P58,0) -> 0 | AR10: =M58 -> 0 | AS10: =IF($U58>=1,VLOOKUP($T58,$J$15:$N$34,3,FALSE)/2,$Q58/2) -> 0 | AT10: =IF(AND(M58=0,N58=0),0,DEGREES(ASIN(AQ10/(SQRT((AQ10^2)+(AR10^2)))))) -> 0 | AU10: =DEGREES(ASIN(O58/(SQRT((O58^2)+(AS10^2))))) -> #DIV/0! | AV10: =(IF(T59="",0,VLOOKUP($T59,$J$15:$N$34,5,FALSE)*U59))+(IF(T58="",0,(VLOOKUP($T58,$J$15:$N$34,5,FALSE)*U58)))+(Q58*R58)+(Q59*R59) -> 0 | AW10: =AX10+AY10+AZ10 -> 0 | AX10: =(2*((IF($D$13>0,$D$13,D26)*F26)+(IF($D$13>0,$D$13,D26)*E26)))-AV10 -> 0 | AY10: =E26*F26 -> 0 | AZ10: =AY10 -> 0 | BA10: =((AZ10*VLOOKUP(H26,$BG$4:$BJ$6,2,FALSE))/AW10)+((AX10*VLOOKUP(H26,$BG$4:$BJ$6,3,FALSE))/AW10)+((AY10*VLOOKUP(H26,$BG$4:$BJ$6,4,FALSE))/AW10) -> #N/A | BB10: =90-AT10-AU10 -> #DIV/0! | BC10: =IF(K21="","",J21) | BE10: Bedroom Three | BF10: 0.015
J11: Define all generic windows in the tale below to create a schedule. Glazing area and visible transmittance are required. | P11: Daylight Factor Calculation Reference Image for Option Two | AP11: =C27 -> - | AQ11: =IF(N60-AQ33-P60>0,N60-AQ33-P60,0) -> 0 | AR11: =M60 -> 0 | AS11: =IF($U60>=1,VLOOKUP($T60,$J$15:$N$34,3,FALSE)/2,$Q60/2) -> 0 | AT11: =IF(AND(M60=0,N60=0),0,DEGREES(ASIN(AQ11/(SQRT((AQ11^2)+(AR11^2)))))) -> 0 | AU11: =DEGREES(ASIN(O60/(SQRT((O60^2)+(AS11^2))))) -> #DIV/0! | AV11: =(IF(T61="",0,VLOOKUP($T61,$J$15:$N$34,5,FALSE)*U61))+(IF(T60="",0,(VLOOKUP($T60,$J$15:$N$34,5,FALSE)*U60)))+(Q60*R60)+(Q61*R61) -> 0 | AW11: =AX11+AY11+AZ11 -> 0 | AX11: =(2*((IF($D$13>0,$D$13,D27)*F27)+(IF($D$13>0,$D$13,D27)*E27)))-AV11 -> 0 | AY11: =E27*F27 -> 0 | AZ11: =AY11 -> 0 | BA11: =((AZ11*VLOOKUP(H27,$BG$4:$BJ$6,2,FALSE))/AW11)+((AX11*VLOOKUP(H27,$BG$4:$BJ$6,3,FALSE))/AW11)+((AY11*VLOOKUP(H27,$BG$4:$BJ$6,4,FALSE))/AW11) -> #N/A | BB11: =90-AT11-AU11 -> #DIV/0! | BC11: =IF(K22="","",J22) | BE11: Bedroom Four | BF11: 0.015
AP12: =C28 -> - | AQ12: =IF(N62-AQ34-P62>0,N62-AQ34-P62,0) -> 0 | AR12: =M62 -> 0 | AS12: =IF($U62>=1,VLOOKUP($T62,$J$15:$N$34,3,FALSE)/2,$Q62/2) -> 0 | AT12: =IF(AND(M62=0,N62=0),0,DEGREES(ASIN(AQ12/(SQRT((AQ12^2)+(AR12^2)))))) -> 0 | AU12: =DEGREES(ASIN(O62/(SQRT((O62^2)+(AS12^2))))) -> #DIV/0! | AV12: =(IF(T63="",0,VLOOKUP($T63,$J$15:$N$34,5,FALSE)*U63))+(IF(T62="",0,(VLOOKUP($T62,$J$15:$N$34,5,FALSE)*U62)))+(Q62*R62)+(Q63*R63) -> 0 | AW12: =AX12+AY12+AZ12 -> 0 | AX12: =(2*((IF($D$13>0,$D$13,D28)*F28)+(IF($D$13>0,$D$13,D28)*E28)))-AV12 -> 0 | AY12: =E28*F28 -> 0 | AZ12: =AY12 -> 0 | BA12: =((AZ12*VLOOKUP(H28,$BG$4:$BJ$6,2,FALSE))/AW12)+((AX12*VLOOKUP(H28,$BG$4:$BJ$6,3,FALSE))/AW12)+((AY12*VLOOKUP(H28,$BG$4:$BJ$6,4,FALSE))/AW12) -> #N/A | BB12: =90-AT12-AU12 -> #DIV/0! | BC12: =IF(K23="","",J23) | BE12: Bedroom Five | BF12: 0.015
C13: Standard wall height | F13: Dwelling Type | G13: =IF(Summary!$D$23=0,$BK$4,IF(Summary!$D$23=1,$BK$5,BK6)) -> 0 | J13: Window Label | K13: Width (m) | L13: Height (m) | M13: Visible Transmittance | N13: Area (m2) | AP13: =C29 -> - | AQ13: =IF(N64-AQ35-P64>0,N64-AQ35-P64,0) -> 0 | AR13: =M64 -> 0 | AS13: =IF($U64>=1,VLOOKUP($T64,$J$15:$N$34,3,FALSE)/2,$Q64/2) -> 0 | AT13: =IF(AND(M64=0,N64=0),0,DEGREES(ASIN(AQ13/(SQRT((AQ13^2)+(AR13^2)))))) -> 0 | AU13: =DEGREES(ASIN(O64/(SQRT((O64^2)+(AS13^2))))) -> #DIV/0! | AV13: =(IF(T65="",0,VLOOKUP($T65,$J$15:$N$34,5,FALSE)*U65))+(IF(T64="",0,(VLOOKUP($T64,$J$15:$N$34,5,FALSE)*U64)))+(Q64*R64)+(Q65*R65) -> 0 | AW13: =AX13+AY13+AZ13 -> 0 | AX13: =(2*((IF($D$13>0,$D$13,D29)*F29)+(IF($D$13>0,$D$13,D29)*E29)))-AV13 -> 0 | AY13: =E29*F29 -> 0 | AZ13: =AY13 -> 0 | BA13: =((AZ13*VLOOKUP(H29,$BG$4:$BJ$6,2,FALSE))/AW13)+((AX13*VLOOKUP(H29,$BG$4:$BJ$6,3,FALSE))/AW13)+((AY13*VLOOKUP(H29,$BG$4:$BJ$6,4,FALSE))/AW13) -> #N/A | BB13: =90-AT13-AU13 -> #DIV/0! | BC13: =IF(K24="","",J24) | BE13: Bedroom Six | BF13: 0.015
C14: Number of Stories | D14: 0 | F14: Calculation Method | G14: One | AP14: =C30 -> - | AQ14: =IF(N66-AQ36-P66>0,N66-AQ36-P66,0) -> 0 | AR14: =M66 -> 0 | AS14: =IF($U66>=1,VLOOKUP($T66,$J$15:$N$34,3,FALSE)/2,$Q66/2) -> 0 | AT14: =IF(AND(M66=0,N66=0),0,DEGREES(ASIN(AQ14/(SQRT((AQ14^2)+(AR14^2)))))) -> 0 | AU14: =DEGREES(ASIN(O66/(SQRT((O66^2)+(AS14^2))))) -> #DIV/0! | AV14: =(IF(T67="",0,VLOOKUP($T67,$J$15:$N$34,5,FALSE)*U67))+(IF(T66="",0,(VLOOKUP($T66,$J$15:$N$34,5,FALSE)*U66)))+(Q66*R66)+(Q67*R67) -> 0 | AW14: =AX14+AY14+AZ14 -> 0 | AX14: =(2*((IF($D$13>0,$D$13,D30)*F30)+(IF($D$13>0,$D$13,D30)*E30)))-AV14 -> 0 | AY14: =E30*F30 -> 0 | AZ14: =AY14 -> 0 | BA14: =((AZ14*VLOOKUP(H30,$BG$4:$BJ$6,2,FALSE))/AW14)+((AX14*VLOOKUP(H30,$BG$4:$BJ$6,3,FALSE))/AW14)+((AY14*VLOOKUP(H30,$BG$4:$BJ$6,4,FALSE))/AW14) -> #N/A | BB14: =90-AT14-AU14 -> #DIV/0! | BC14: =IF(K25="","",J25) | BE14: Bedroom Seven | BF14: 0.015
J15: Window 1 | K15: 2 | L15: 1.5 | M15: 90 | N15: =K15*L15 -> 3 | AP15: =C31 -> - | AQ15: =IF(N68-AQ37-P68>0,N68-AQ37-P68,0) -> 0 | AR15: =M68 -> 0 | AS15: =IF($U68>=1,VLOOKUP($T68,$J$15:$N$34,3,FALSE)/2,$Q68/2) -> 0 | AT15: =IF(AND(M68=0,N68=0),0,DEGREES(ASIN(AQ15/(SQRT((AQ15^2)+(AR15^2)))))) -> 0 | AU15: =DEGREES(ASIN(O68/(SQRT((O68^2)+(AS15^2))))) -> #DIV/0! | AV15: =(IF(T69="",0,VLOOKUP($T69,$J$15:$N$34,5,FALSE)*U69))+(IF(T68="",0,(VLOOKUP($T68,$J$15:$N$34,5,FALSE)*U68)))+(Q68*R68)+(Q69*R69) -> 0 | AW15: =AX15+AY15+AZ15 -> 0 | AX15: =(2*((IF($D$13>0,$D$13,D31)*F31)+(IF($D$13>0,$D$13,D31)*E31)))-AV15 -> 0 | AY15: =E31*F31 -> 0 | AZ15: =AY15 -> 0 | BA15: =((AZ15*VLOOKUP(H31,$BG$4:$BJ$6,2,FALSE))/AW15)+((AX15*VLOOKUP(H31,$BG$4:$BJ$6,3,FALSE))/AW15)+((AY15*VLOOKUP(H31,$BG$4:$BJ$6,4,FALSE))/AW15) -> #N/A | BB15: =90-AT15-AU15 -> #DIV/0! | BC15: =IF(K26="","",J26) | BE15: Bedroom Eight | BF15: 0.015
C16: Define dwelling spaces by selecting "-" and determining a space name from the list. Then supply room dimensions, story, and reflectance's. If a standard wall hight has been used, one doesn't need to be input. | J16: =IF(N15>0,"Window 2","") -> Window 2 | K16: 1.2 | L16: 1.5 | N16: =K16*L16 -> 1.8 | AP16: =C32 -> - | AQ16: =IF(N70-AQ38-P70>0,N70-AQ38-P70,0) -> 0 | AR16: =M70 -> 0 | AS16: =IF($U70>=1,VLOOKUP($T70,$J$15:$N$34,3,FALSE)/2,$Q70/2) -> 0 | AT16: =IF(AND(M70=0,N70=0),0,DEGREES(ASIN(AQ16/(SQRT((AQ16^2)+(AR16^2)))))) -> 0 | AU16: =DEGREES(ASIN(O70/(SQRT((O70^2)+(AS16^2))))) -> #DIV/0! | AV16: =(IF(T71="",0,VLOOKUP($T71,$J$15:$N$34,5,FALSE)*U71))+(IF(T70="",0,(VLOOKUP($T70,$J$15:$N$34,5,FALSE)*U70)))+(Q70*R70)+(Q71*R71) -> 0 | AW16: =AX16+AY16+AZ16 -> 0 | AX16: =(2*((IF($D$13>0,$D$13,D32)*F32)+(IF($D$13>0,$D$13,D32)*E32)))-AV16 -> 0 | AY16: =E32*F32 -> 0 | AZ16: =AY16 -> 0 | BA16: =((AZ16*VLOOKUP(H32,$BG$4:$BJ$6,2,FALSE))/AW16)+((AX16*VLOOKUP(H32,$BG$4:$BJ$6,3,FALSE))/AW16)+((AY16*VLOOKUP(H32,$BG$4:$BJ$6,4,FALSE))/AW16) -> #N/A | BB16: =90-AT16-AU16 -> #DIV/0! | BC16: =IF(K27="","",J27) | BE16: Bedroom Nine | BF16: 0.015
J17: =IF(N16>0,"Window 3","") -> Window 3 | N17: =K17*L17 -> 0 | AP17: =C33 -> - | AQ17: =IF(N72-AQ39-P72>0,N72-AQ39-P72,0) -> 0 | AR17: =M72 -> 0 | AS17: =IF($U72>=1,VLOOKUP($T72,$J$15:$N$34,3,FALSE)/2,$Q72/2) -> 0 | AT17: =IF(AND(M72=0,N72=0),0,DEGREES(ASIN(AQ17/(SQRT((AQ17^2)+(AR17^2)))))) -> 0 | AU17: =DEGREES(ASIN(O72/(SQRT((O72^2)+(AS17^2))))) -> #DIV/0! | AV17: =(IF(T73="",0,VLOOKUP($T73,$J$15:$N$34,5,FALSE)*U73))+(IF(T72="",0,(VLOOKUP($T72,$J$15:$N$34,5,FALSE)*U72)))+(Q72*R72)+(Q73*R73) -> 0 | AW17: =AX17+AY17+AZ17 -> 0 | AX17: =(2*((IF($D$13>0,$D$13,D33)*F33)+(IF($D$13>0,$D$13,D33)*E33)))-AV17 -> 0 | AY17: =E33*F33 -> 0 | AZ17: =AY17 -> 0 | BA17: =((AZ17*VLOOKUP(H33,$BG$4:$BJ$6,2,FALSE))/AW17)+((AX17*VLOOKUP(H33,$BG$4:$BJ$6,3,FALSE))/AW17)+((AY17*VLOOKUP(H33,$BG$4:$BJ$6,4,FALSE))/AW17) -> #N/A | BB17: =90-AT17-AU17 -> #DIV/0! | BC17: =IF(K28="","",J28) | BE17: Bedroom Ten | BF17: 0.015
C18: Space Name | D18: =IF(D13>0,"","Wall Height (m)") -> Wall Height (m) | E18: Floor Width (m) | F18: Floor Length (m) | G18: Story | H18: Surface Reflectance | J18: =IF(N17>0,"Window 4","") | N18: =K18*L18 -> 0 | BC18: =IF(K29="","",J29) | BD18: Not Significantly
J19: =IF(N18>0,"Window 5","") | N19: =K19*L19 -> 0 | BC19: =IF(K30="","",J30) | BD19: Significantly
C20: Main Bedroom | D20: 2.5 | J20: =IF(N19>0,"Window 6","") | N20: =K20*L20 -> 0 | BC20: =IF(K31="","",J31)
C21: Bedroom Two | D21: 1 | J21: =IF(N20>0,"Window 7","") | N21: =K21*L21 -> 0 | BC21: =IF(K32="","",J32)
C22: - | J22: =IF(N21>0,"Window 8","") | N22: =K22*L22 -> 0 | AR22: Medium | AS22: 0.7 | AT22: 0.4 | AU22: 0.2 | AW22: Option One | BC22: =IF(K33="","",J33) | BD22: Option Two
C23: - | J23: =IF(N22>0,"Window 9","") | N23: =K23*L23 -> 0 | AO23: =$J15 -> Window 1 | AP23: =$N15*$M15 -> 270 | AR23: High | AS23: 0.7 | AT23: 0.6 | AU23: 0.4 | AW23: Studio | AX23: 1 bedroom dwelling | AZ23: 2+ bedroom dwelling | BC23: =IF(K34="","",J34) | BD23: Studio | BE23: 1 bedroom dwelling | BG23: 2+ bedroom dwelling
C24: - | J24: =IF(N23>0,"Window 10","") | N24: =K24*L24 -> 0 | AO24: =$J16 -> Window 2 | AP24: =$N16*$M16 -> 0 | AS24: - | AT24: Spaces | AW24: =IFERROR(IF(SUM(AW26:AW40)/COUNTIF(AW26:AW40,">=0")=1,3,0),0) -> 0 | AX24: =IFERROR(IF(SUM(AX26:AX40)/COUNTIF(AX26:AX40,">=0")=1,2,0),0) -> 0 | AY24: =IFERROR(IF(SUM(AY26:AY40)/COUNTIF(AY26:AY40,">=0")=1,1,0),0) -> 0 | AZ24: =IFERROR(IF(SUM(AZ26:AZ40)/COUNTIF(AZ26:AZ40,">=0")=1,1,0),0) -> 0 | BA24: =IFERROR(IF(SUM(BA26:BA40)/COUNTIF(BA26:BA40,">=0")=1,1,0),0) -> 0 | BB24: =IFERROR(IF(SUM(BB26:BB40)/COUNTIF(BB26:BB40,">=0")=1,1,0),0) -> 0 | BC24: =IF(K35="","",J35) | BD24: =IFERROR(IF(SUM(BD26:BD35)/COUNTIF(BD26:BD35,">=0")=1,3,0),0) -> 0 | BE24: =IFERROR(IF(SUM(BE26:BE35)/COUNTIF(BE26:BE35,">=0")=1,2,0),0) -> 0 | BF24: =IFERROR(IF(SUM(BF26:BF35)/COUNTIF(BF26:BF35,">=0")=1,1,0),0) -> 0 | BG24: =IFERROR(IF(SUM(BG26:BG35)/COUNTIF(BG26:BG35,">=0")=1,1,0),0) -> 0 | BH24: =IFERROR(IF(SUM(BH26:BH35)/COUNTIF(BH26:BH35,">=0")=1,1,0),0) -> 0 | BI24: =IFERROR(IF(SUM(BI26:BI35)/COUNTIF(BI26:BI35,">=0")=1,1,0),0) -> 0
C25: - | J25: =IF(N24>0,"Window 11","") | N25: =K25*L25 -> 0 | AO25: =$J17 -> Window 3 | AP25: =$N17*$M17 -> 0 | AW25: Habitable | AX25: Living Kitchen | AY25: Bedroom | AZ25: Living Kitchen | BA25: M Bedroom | BB25: Bedroom | BC25: =IF(K36="","",J36) | BD25: Habitable | BE25: Living Kitchen | BF25: Bedroom | BG25: Living Kitchen | BH25: M Bedroom | BI25: Bedroom
C26: - | J26: =IF(N25>0,"Window 12","") | N26: =K26*L26 -> 0 | AO26: =$J18 | AP26: =$N18*$M18 -> 0 | AQ26: =VALUE(CONCATENATE(IF($G20="Ground",0,0),IF($G20=2,$D$13,0),IF($G20=3,2*$D$13,0),IF($G20=4,3*$D$13,0))) -> 0 | AR26: =IFERROR(CONCATENATE(IF($D$14=1,"Ground",""),IF($D$14=2,"Ground",""),IF($D$14=3,"Ground",""),IF($D$14=4,"Ground",""),IF($D$14="","","")),"") | AS26: {=IFERROR(INDEX(AT$26:AT$54, MATCH(0, INDEX( COUNTIF( AS$25:AS25, AT$26:AT$54)+ (COUNTIF( AT$26:AT$54, AT$26:AT$54)<>1),), 0)),"")} -> Living Room One | AT26: Living Room One | AU26: 0.015 | AV26: =C44 -> Main Bedroom | AW26: =IF(OR(C44=$BE$4,C44=$BE$5,C44=$BE$8,C44=$BE$9,C44=$BE$10,C44=$BE$11,C44=$BE$12,C44=$BE$13,C44=$BE$14,C44=$BE$15,C44=$BE$16,C44=$BE$17),IF(I44="Yes",1,0),"") -> 0 | AX26: =IF(OR(C44=$BE$4,C44=$BE$5,C44=$BE$6,C44=$BE$7),IF(I44="Yes",1,0),"") | AY26: =IF(OR(C44=$BE$8),IF(I44="Yes",1,0),"") -> 0 | AZ26: =IF(OR(C44=$BE$4,C44=$BE$5,C44=$BE$6,C44=$BE$7),IF(I44="Yes",1,0),"") | BA26: =IF(OR(C44=$BE$8),IF(I44="Yes",1,0),"") -> 0 | BB26: =IF(OR(C44=$BE$9,C44=$BE$10,C44=$BE$11,C44=$BE$12,C44=$BE$13,C44=$BE$14,C44=$BE$15,C44=$BE$16,C44=$BE$17),IF(I44="Yes",1,0),"") | BC26: =AV26 -> Main Bedroom | BD26: =IF(OR(L45=$BE$4,L45=$BE$5,L45=$BE$8,L45=$BE$9,L45=$BE$10,L45=$BE$11,L45=$BE$12,L45=$BE$13,L45=$BE$14,L45=$BE$15,L45=$BE$16,L45=$BE$17),IF(W45="Yes",1,0),"") -> 0 | BE26: =IF(OR(L45=$BE$4,L45=$BE$5,L45=$BE$6,L45=$BE$7),IF(W45="Yes",1,0),"") | BF26: =IF(OR(L45=$BE$8),IF(W45="Yes",1,0),"") -> 0 | BG26: =IF(OR(L45=$BE$4,L45=$BE$5,L45=$BE$6,L45=$BE$7),IF(W45="Yes",1,0),"") | BH26: =IF(OR(L45=$BE$8),IF(W45="Yes",1,0),"") -> 0 | BI26: =IF(OR(L45=$BE$9,L45=$BE$10,L45=$BE$11,L45=$BE$12,L45=$BE$13,L45=$BE$14,L45=$BE$15,L45=$BE$16,L45=$BE$17),IF(P44="Yes",1,0),"")
C27: - | J27: =IF(N26>0,"Window 13","") | N27: =K27*L27 -> 0 | AO27: =$J19 | AP27: =$N19*$M19 -> 0 | AQ27: =VALUE(CONCATENATE(IF($G21="Ground",0,0),IF($G21=2,$D$13,0),IF($G21=3,2*$D$13,0),IF($G21=4,3*$D$13,0))) -> 0 | AR27: =IFERROR(VALUE(CONCATENATE(IF($D$14=1,"",""),IF($D$14=2,2,""),IF($D$14=3,2,""),IF($D$14=4,2,""))),"") | AS27: {=IFERROR(INDEX(AT$26:AT$54, MATCH(0, INDEX( COUNTIF( AS$25:AS26, AT$26:AT$54)+ (COUNTIF( AT$26:AT$54, AT$26:AT$54)<>1),), 0)),"")} -> Living Room Two | AT27: Living Room Two | AU27: 0.015 | AV27: =C45 -> Bedroom Two | AW27: =IF(OR(C45=$BE$4,C45=$BE$5,C45=$BE$8,C45=$BE$9,C45=$BE$10,C45=$BE$11,C45=$BE$12,C45=$BE$13,C45=$BE$14,C45=$BE$15,C45=$BE$16,C45=$BE$17),IF(I45="Yes",1,0),"") -> 0 | AX27: =IF(OR(C45=$BE$4,C45=$BE$5,C45=$BE$6,C45=$BE$7),IF(I45="Yes",1,0),"") | AY27: =IF(OR(C45=$BE$8),IF(I45="Yes",1,0),"") | AZ27: =IF(OR(C45=$BE$4,C45=$BE$5,C45=$BE$6,C45=$BE$7),IF(I45="Yes",1,0),"") | BA27: =IF(OR(C45=$BE$8),IF(I45="Yes",1,0),"") | BB27: =IF(OR(C45=$BE$9,C45=$BE$10,C45=$BE$11,C45=$BE$12,C45=$BE$13,C45=$BE$14,C45=$BE$15,C45=$BE$16,C45=$BE$17),IF(I45="Yes",1,0),"") -> 0 | BC27: =AV27 -> Bedroom Two | BD27: =IF(OR(L48=$BE$4,L48=$BE$5,L48=$BE$8,L48=$BE$9,L48=$BE$10,L48=$BE$11,L48=$BE$12,L48=$BE$13,L48=$BE$14,L48=$BE$15,L48=$BE$16,L48=$BE$17),IF(W48="Yes",1,0),"") -> 0 | BE27: =IF(OR(L48=$BE$4,L48=$BE$5,L48=$BE$6,L48=$BE$7),IF(W48="Yes",1,0),"") | BF27: =IF(OR(L48=$BE$8),IF(W48="Yes",1,0),"") | BG27: =IF(OR(L48=$BE$4,L48=$BE$5,L48=$BE$6,L48=$BE$7),IF(W48="Yes",1,0),"") | BH27: =IF(OR(L48=$BE$8),IF(W48="Yes",1,0),"") | BI27: =IF(OR(L48=$BE$9,L48=$BE$10,L48=$BE$11,L48=$BE$12,L48=$BE$13,L48=$BE$14,L48=$BE$15,L48=$BE$16,L48=$BE$17),IF(W48="Yes",1,0),"") -> 0
C28: - | J28: =IF(N27>0,"Window 14","") | N28: =K28*L28 -> 0 | AO28: =$J20 | AP28: =$N20*$M20 -> 0 | AQ28: =VALUE(CONCATENATE(IF($G22="Ground",0,0),IF($G22=2,$D$13,0),IF($G22=3,2*$D$13,0),IF($G22=4,3*$D$13,0))) -> 0 | AR28: =IFERROR(VALUE(CONCATENATE(IF($D$14=1,"",""),IF($D$14=2,"",""),IF($D$14=3,3,""),IF($D$14=4,3,""),IF($D$14="","",""))),"") | AS28: {=IFERROR(INDEX(AT$26:AT$54, MATCH(0, INDEX( COUNTIF( AS$25:AS27, AT$26:AT$54)+ (COUNTIF( AT$26:AT$54, AT$26:AT$54)<>1),), 0)),"")} -> Living Room Three | AT28: Living Room Three | AU28: 0.015 | AV28: =C46 -> - | AW28: =IF(OR(C46=$BE$4,C46=$BE$5,C46=$BE$8,C46=$BE$9,C46=$BE$10,C46=$BE$11,C46=$BE$12,C46=$BE$13,C46=$BE$14,C46=$BE$15,C46=$BE$16,C46=$BE$17),IF(I46="Yes",1,0),"") | AX28: =IF(OR(C46=$BE$4,C46=$BE$5,C46=$BE$6,C46=$BE$7),IF(I46="Yes",1,0),"") | AY28: =IF(OR(C46=$BE$8),IF(I46="Yes",1,0),"") | AZ28: =IF(OR(C46=$BE$4,C46=$BE$5,C46=$BE$6,C46=$BE$7),IF(I46="Yes",1,0),"") | BA28: =IF(OR(C46=$BE$8),IF(I46="Yes",1,0),"") | BB28: =IF(OR(C46=$BE$9,C46=$BE$10,C46=$BE$11,C46=$BE$12,C46=$BE$13,C46=$BE$14,C46=$BE$15,C46=$BE$16,C46=$BE$17),IF(I46="Yes",1,0),"") | BC28: =AV28 -> - | BD28: =IF(OR(L50=$BE$4,L50=$BE$5,L50=$BE$8,L50=$BE$9,L50=$BE$10,L50=$BE$11,L50=$BE$12,L50=$BE$13,L50=$BE$14,L50=$BE$15,L50=$BE$16,L50=$BE$17),IF(W50="Yes",1,0),"") | BE28: =IF(OR(L50=$BE$4,L50=$BE$5,L50=$BE$6,L50=$BE$7),IF(W50="Yes",1,0),"") | BF28: =IF(OR(L50=$BE$8),IF(W50="Yes",1,0),"") | BG28: =IF(OR(L50=$BE$4,L50=$BE$5,L50=$BE$6,L50=$BE$7),IF(W50="Yes",1,0),"") | BH28: =IF(OR(L50=$BE$8),IF(W50="Yes",1,0),"") | BI28: =IF(OR(L50=$BE$9,L50=$BE$10,L50=$BE$11,L50=$BE$12,L50=$BE$13,L50=$BE$14,L50=$BE$15,L50=$BE$16,L50=$BE$17),IF(W50="Yes",1,0),"")
C29: - | J29: =IF(N28>0,"Window 15","") | N29: =K29*L29 -> 0 | AO29: =$J21 | AP29: =$N21*$M21 -> 0 | AQ29: =VALUE(CONCATENATE(IF($G23="Ground",0,0),IF($G23=2,$D$13,0),IF($G23=3,2*$D$13,0),IF($G23=4,3*$D$13,0))) -> 0 | AR29: =IFERROR(VALUE(CONCATENATE(IF($D$14=1,"",""),IF($D$14=2,"",""),IF($D$14=3,"",""),IF($D$14=4,4,""),IF($D$14="","",""))),"") | AS29: {=IFERROR(INDEX(AT$26:AT$54, MATCH(0, INDEX( COUNTIF( AS$25:AS28, AT$26:AT$54)+ (COUNTIF( AT$26:AT$54, AT$26:AT$54)<>1),), 0)),"")} -> Living Room Four | AT29: Living Room Four | AU29: 0.015 | AV29: =C47 -> - | AW29: =IF(OR(C47=$BE$4,C47=$BE$5,C47=$BE$8,C47=$BE$9,C47=$BE$10,C47=$BE$11,C47=$BE$12,C47=$BE$13,C47=$BE$14,C47=$BE$15,C47=$BE$16,C47=$BE$17),IF(I47="Yes",1,0),"") | AX29: =IF(OR(C47=$BE$4,C47=$BE$5,C47=$BE$6,C47=$BE$7),IF(I47="Yes",1,0),"") | AY29: =IF(OR(C47=$BE$8),IF(I47="Yes",1,0),"") | AZ29: =IF(OR(C47=$BE$4,C47=$BE$5,C47=$BE$6,C47=$BE$7),IF(I47="Yes",1,0),"") | BA29: =IF(OR(C47=$BE$8),IF(I47="Yes",1,0),"") | BB29: =IF(OR(C47=$BE$9,C47=$BE$10,C47=$BE$11,C47=$BE$12,C47=$BE$13,C47=$BE$14,C47=$BE$15,C47=$BE$16,C47=$BE$17),IF(I47="Yes",1,0),"") | BC29: =AV29 -> - | BD29: =IF(OR(L52=$BE$4,L52=$BE$5,L52=$BE$8,L52=$BE$9,L52=$BE$10,L52=$BE$11,L52=$BE$12,L52=$BE$13,L52=$BE$14,L52=$BE$15,L52=$BE$16,L52=$BE$17),IF(W52="Yes",1,0),"") | BE29: =IF(OR(L52=$BE$4,L52=$BE$5,L52=$BE$6,L52=$BE$7),IF(W52="Yes",1,0),"") | BF29: =IF(OR(L52=$BE$8),IF(W52="Yes",1,0),"") | BG29: =IF(OR(L52=$BE$4,L52=$BE$5,L52=$BE$6,L52=$BE$7),IF(W52="Yes",1,0),"") | BH29: =IF(OR(L52=$BE$8),IF(W52="Yes",1,0),"") | BI29: =IF(OR(L52=$BE$9,L52=$BE$10,L52=$BE$11,L52=$BE$12,L52=$BE$13,L52=$BE$14,L52=$BE$15,L52=$BE$16,L52=$BE$17),IF(W52="Yes",1,0),"")
C30: - | J30: =IF(N29>0,"Window 16","") | N30: =K30*L30 -> 0 | AO30: =$J22 | AP30: =$N22*$M22 -> 0 | AQ30: =VALUE(CONCATENATE(IF($G24="Ground",0,0),IF($G24=2,$D$13,0),IF($G24=3,2*$D$13,0),IF($G24=4,3*$D$13,0))) -> 0 | AS30: {=IFERROR(INDEX(AT$26:AT$54, MATCH(0, INDEX( COUNTIF( AS$25:AS29, AT$26:AT$54)+ (COUNTIF( AT$26:AT$54, AT$26:AT$54)<>1),), 0)),"")} -> Kitchen One | AT30: Kitchen One | AU30: 0.02 | AV30: =C48 -> - | AW30: =IF(OR(C48=$BE$4,C48=$BE$5,C48=$BE$8,C48=$BE$9,C48=$BE$10,C48=$BE$11,C48=$BE$12,C48=$BE$13,C48=$BE$14,C48=$BE$15,C48=$BE$16,C48=$BE$17),IF(I48="Yes",1,0),"") | AX30: =IF(OR(C48=$BE$4,C48=$BE$5,C48=$BE$6,C48=$BE$7),IF(I48="Yes",1,0),"") | AY30: =IF(OR(C48=$BE$8),IF(I48="Yes",1,0),"") | AZ30: =IF(OR(C48=$BE$4,C48=$BE$5,C48=$BE$6,C48=$BE$7),IF(I48="Yes",1,0),"") | BA30: =IF(OR(C48=$BE$8),IF(I48="Yes",1,0),"") | BB30: =IF(OR(C48=$BE$9,C48=$BE$10,C48=$BE$11,C48=$BE$12,C48=$BE$13,C48=$BE$14,C48=$BE$15,C48=$BE$16,C48=$BE$17),IF(I48="Yes",1,0),"") | BC30: =AV30 -> - | BD30: =IF(OR(L54=$BE$4,L54=$BE$5,L54=$BE$8,L54=$BE$9,L54=$BE$10,L54=$BE$11,L54=$BE$12,L54=$BE$13,L54=$BE$14,L54=$BE$15,L54=$BE$16,L54=$BE$17),IF(W54="Yes",1,0),"") | BE30: =IF(OR(L54=$BE$4,L54=$BE$5,L54=$BE$6,L54=$BE$7),IF(W54="Yes",1,0),"") | BF30: =IF(OR(L54=$BE$8),IF(W54="Yes",1,0),"") | BG30: =IF(OR(L54=$BE$4,L54=$BE$5,L54=$BE$6,L54=$BE$7),IF(W54="Yes",1,0),"") | BH30: =IF(OR(L54=$BE$8),IF(W54="Yes",1,0),"") | BI30: =IF(OR(L54=$BE$9,L54=$BE$10,L54=$BE$11,L54=$BE$12,L54=$BE$13,L54=$BE$14,L54=$BE$15,L54=$BE$16,L54=$BE$17),IF(W54="Yes",1,0),"")
C31: - | J31: =IF(N30>0,"Window 17","") | N31: =K31*L31 -> 0 | AO31: =$J23 | AP31: =$N23*$M23 -> 0 | AQ31: =VALUE(CONCATENATE(IF($G25="Ground",0,0),IF($G25=2,$D$13,0),IF($G25=3,2*$D$13,0),IF($G25=4,3*$D$13,0))) -> 0 | AS31: {=IFERROR(INDEX(AT$26:AT$54, MATCH(0, INDEX( COUNTIF( AS$25:AS30, AT$26:AT$54)+ (COUNTIF( AT$26:AT$54, AT$26:AT$54)<>1),), 0)),"")} -> Kitchen Two | AT31: Kitchen Two | AU31: 0.02 | AV31: =C49 -> - | AW31: =IF(OR(C49=$BE$4,C49=$BE$5,C49=$BE$8,C49=$BE$9,C49=$BE$10,C49=$BE$11,C49=$BE$12,C49=$BE$13,C49=$BE$14,C49=$BE$15,C49=$BE$16,C49=$BE$17),IF(I49="Yes",1,0),"") | AX31: =IF(OR(C49=$BE$4,C49=$BE$5,C49=$BE$6,C49=$BE$7),IF(I49="Yes",1,0),"") | AY31: =IF(OR(C49=$BE$8),IF(I49="Yes",1,0),"") | AZ31: =IF(OR(C49=$BE$4,C49=$BE$5,C49=$BE$6,C49=$BE$7),IF(I49="Yes",1,0),"") | BA31: =IF(OR(C49=$BE$8),IF(I49="Yes",1,0),"") | BB31: =IF(OR(C49=$BE$9,C49=$BE$10,C49=$BE$11,C49=$BE$12,C49=$BE$13,C49=$BE$14,C49=$BE$15,C49=$BE$16,C49=$BE$17),IF(I49="Yes",1,0),"") | BC31: =AV31 -> - | BD31: =IF(OR(L56=$BE$4,L56=$BE$5,L56=$BE$8,L56=$BE$9,L56=$BE$10,L56=$BE$11,L56=$BE$12,L56=$BE$13,L56=$BE$14,L56=$BE$15,L56=$BE$16,L56=$BE$17),IF(W56="Yes",1,0),"") | BE31: =IF(OR(L56=$BE$4,L56=$BE$5,L56=$BE$6,L56=$BE$7),IF(W56="Yes",1,0),"") | BF31: =IF(OR(L56=$BE$8),IF(W56="Yes",1,0),"") | BG31: =IF(OR(L56=$BE$4,L56=$BE$5,L56=$BE$6,L56=$BE$7),IF(W56="Yes",1,0),"") | BH31: =IF(OR(L56=$BE$8),IF(W56="Yes",1,0),"") | BI31: =IF(OR(L56=$BE$9,L56=$BE$10,L56=$BE$11,L56=$BE$12,L56=$BE$13,L56=$BE$14,L56=$BE$15,L56=$BE$16,L56=$BE$17),IF(W56="Yes",1,0),"")
C32: - | J32: =IF(N31>0,"Window 18","") | N32: =K32*L32 -> 0 | AO32: =$J24 | AP32: =$N24*$M24 -> 0 | AQ32: =VALUE(CONCATENATE(IF($G26="Ground",0,0),IF($G26=2,$D$13,0),IF($G26=3,2*$D$13,0),IF($G26=4,3*$D$13,0))) -> 0 | AS32: {=IFERROR(INDEX(AT$26:AT$54, MATCH(0, INDEX( COUNTIF( AS$25:AS31, AT$26:AT$54)+ (COUNTIF( AT$26:AT$54, AT$26:AT$54)<>1),), 0)),"")} -> Bedroom Three | AT32: Main Bedroom | AU32: 0.015 | AV32: =C50 -> - | AW32: =IF(OR(C50=$BE$4,C50=$BE$5,C50=$BE$8,C50=$BE$9,C50=$BE$10,C50=$BE$11,C50=$BE$12,C50=$BE$13,C50=$BE$14,C50=$BE$15,C50=$BE$16,C50=$BE$17),IF(I50="Yes",1,0),"") | AX32: =IF(OR(C50=$BE$4,C50=$BE$5,C50=$BE$6,C50=$BE$7),IF(I50="Yes",1,0),"") | AY32: =IF(OR(C50=$BE$8),IF(I50="Yes",1,0),"") | AZ32: =IF(OR(C50=$BE$4,C50=$BE$5,C50=$BE$6,C50=$BE$7),IF(I50="Yes",1,0),"") | BA32: =IF(OR(C50=$BE$8),IF(I50="Yes",1,0),"") | BB32: =IF(OR(C50=$BE$9,C50=$BE$10,C50=$BE$11,C50=$BE$12,C50=$BE$13,C50=$BE$14,C50=$BE$15,C50=$BE$16,C50=$BE$17),IF(I50="Yes",1,0),"") | BC32: =AV32 -> - | BD32: =IF(OR(L58=$BE$4,L58=$BE$5,L58=$BE$8,L58=$BE$9,L58=$BE$10,L58=$BE$11,L58=$BE$12,L58=$BE$13,L58=$BE$14,L58=$BE$15,L58=$BE$16,L58=$BE$17),IF(W58="Yes",1,0),"") | BE32: =IF(OR(L58=$BE$4,L58=$BE$5,L58=$BE$6,L58=$BE$7),IF(W58="Yes",1,0),"") | BF32: =IF(OR(L58=$BE$8),IF(W58="Yes",1,0),"") | BG32: =IF(OR(L58=$BE$4,L58=$BE$5,L58=$BE$6,L58=$BE$7),IF(W58="Yes",1,0),"") | BH32: =IF(OR(L58=$BE$8),IF(W58="Yes",1,0),"") | BI32: =IF(OR(L58=$BE$9,L58=$BE$10,L58=$BE$11,L58=$BE$12,L58=$BE$13,L58=$BE$14,L58=$BE$15,L58=$BE$16,L58=$BE$17),IF(W58="Yes",1,0),"")
C33: - | J33: =IF(N32>0,"Window 19","") | N33: =K33*L33 -> 0 | AO33: =$J25 | AP33: =$N25*$M25 -> 0 | AQ33: =VALUE(CONCATENATE(IF($G27="Ground",0,0),IF($G27=2,$D$13,0),IF($G27=3,2*$D$13,0),IF($G27=4,3*$D$13,0))) -> 0 | AS33: {=IFERROR(INDEX(AT$26:AT$54, MATCH(0, INDEX( COUNTIF( AS$25:AS32, AT$26:AT$54)+ (COUNTIF( AT$26:AT$54, AT$26:AT$54)<>1),), 0)),"")} -> Bedroom Four | AT33: Bedroom Two | AU33: 0.015 | AV33: =C51 -> - | AW33: =IF(OR(C51=$BE$4,C51=$BE$5,C51=$BE$8,C51=$BE$9,C51=$BE$10,C51=$BE$11,C51=$BE$12,C51=$BE$13,C51=$BE$14,C51=$BE$15,C51=$BE$16,C51=$BE$17),IF(I51="Yes",1,0),"") | AX33: =IF(OR(C51=$BE$4,C51=$BE$5,C51=$BE$6,C51=$BE$7),IF(I51="Yes",1,0),"") | AY33: =IF(OR(C51=$BE$8),IF(I51="Yes",1,0),"") | AZ33: =IF(OR(C51=$BE$4,C51=$BE$5,C51=$BE$6,C51=$BE$7),IF(I51="Yes",1,0),"") | BA33: =IF(OR(C51=$BE$8),IF(I51="Yes",1,0),"") | BB33: =IF(OR(C51=$BE$9,C51=$BE$10,C51=$BE$11,C51=$BE$12,C51=$BE$13,C51=$BE$14,C51=$BE$15,C51=$BE$16,C51=$BE$17),IF(I51="Yes",1,0),"") | BC33: =AV33 -> - | BD33: =IF(OR(L60=$BE$4,L60=$BE$5,L60=$BE$8,L60=$BE$9,L60=$BE$10,L60=$BE$11,L60=$BE$12,L60=$BE$13,L60=$BE$14,L60=$BE$15,L60=$BE$16,L60=$BE$17),IF(W60="Yes",1,0),"") | BE33: =IF(OR(L60=$BE$4,L60=$BE$5,L60=$BE$6,L60=$BE$7),IF(W60="Yes",1,0),"") | BF33: =IF(OR(L60=$BE$8),IF(W60="Yes",1,0),"") | BG33: =IF(OR(L60=$BE$4,L60=$BE$5,L60=$BE$6,L60=$BE$7),IF(W60="Yes",1,0),"") | BH33: =IF(OR(L60=$BE$8),IF(W60="Yes",1,0),"") | BI33: =IF(OR(L60=$BE$9,L60=$BE$10,L60=$BE$11,L60=$BE$12,L60=$BE$13,L60=$BE$14,L60=$BE$15,L60=$BE$16,L60=$BE$17),IF(W60="Yes",1,0),"")
C34: - | J34: =IF(N33>0,"Window 20","") | N34: =K34*L34 -> 0 | AO34: =$J26 | AP34: =$N26*$M26 -> 0 | AQ34: =VALUE(CONCATENATE(IF($G28="Ground",0,0),IF($G28=2,$D$13,0),IF($G28=3,2*$D$13,0),IF($G28=4,3*$D$13,0))) -> 0 | AS34: {=IFERROR(INDEX(AT$26:AT$54, MATCH(0, INDEX( COUNTIF( AS$25:AS33, AT$26:AT$54)+ (COUNTIF( AT$26:AT$54, AT$26:AT$54)<>1),), 0)),"")} -> Bedroom Five | AT34: Bedroom Three | AU34: 0.015 | AV34: =C52 -> - | AW34: =IF(OR(C52=$BE$4,C52=$BE$5,C52=$BE$8,C52=$BE$9,C52=$BE$10,C52=$BE$11,C52=$BE$12,C52=$BE$13,C52=$BE$14,C52=$BE$15,C52=$BE$16,C52=$BE$17),IF(I52="Yes",1,0),"") | AX34: =IF(OR(C52=$BE$4,C52=$BE$5,C52=$BE$6,C52=$BE$7),IF(I52="Yes",1,0),"") | AY34: =IF(OR(C52=$BE$8),IF(I52="Yes",1,0),"") | AZ34: =IF(OR(C52=$BE$4,C52=$BE$5,C52=$BE$6,C52=$BE$7),IF(I52="Yes",1,0),"") | BA34: =IF(OR(C52=$BE$8),IF(I52="Yes",1,0),"") | BB34: =IF(OR(C52=$BE$9,C52=$BE$10,C52=$BE$11,C52=$BE$12,C52=$BE$13,C52=$BE$14,C52=$BE$15,C52=$BE$16,C52=$BE$17),IF(I52="Yes",1,0),"") | BC34: =AV34 -> - | BD34: =IF(OR(L62=$BE$4,L62=$BE$5,L62=$BE$8,L62=$BE$9,L62=$BE$10,L62=$BE$11,L62=$BE$12,L62=$BE$13,L62=$BE$14,L62=$BE$15,L62=$BE$16,L62=$BE$17),IF(W62="Yes",1,0),"") | BE34: =IF(OR(L62=$BE$4,L62=$BE$5,L62=$BE$6,L62=$BE$7),IF(W62="Yes",1,0),"") | BF34: =IF(OR(L62=$BE$8),IF(W62="Yes",1,0),"") | BG34: =IF(OR(L62=$BE$4,L62=$BE$5,L62=$BE$6,L62=$BE$7),IF(W62="Yes",1,0),"") | BH34: =IF(OR(L62=$BE$8),IF(W62="Yes",1,0),"") | BI34: =IF(OR(L62=$BE$9,L62=$BE$10,L62=$BE$11,L62=$BE$12,L62=$BE$13,L62=$BE$14,L62=$BE$15,L62=$BE$16,L62=$BE$17),IF(W62="Yes",1,0),"")
AO35: =$J27 | AP35: =$N27*$M27 -> 0 | AQ35: =VALUE(CONCATENATE(IF($G29="Ground",0,0),IF($G29=2,$D$13,0),IF($G29=3,2*$D$13,0),IF($G29=4,3*$D$13,0))) -> 0 | AS35: {=IFERROR(INDEX(AT$26:AT$54, MATCH(0, INDEX( COUNTIF( AS$25:AS34, AT$26:AT$54)+ (COUNTIF( AT$26:AT$54, AT$26:AT$54)<>1),), 0)),"")} -> Bedroom Six | AT35: Bedroom Four | AU35: 0.015 | AV35: =C53 -> - | AW35: =IF(OR(C53=$BE$4,C53=$BE$5,C53=$BE$8,C53=$BE$9,C53=$BE$10,C53=$BE$11,C53=$BE$12,C53=$BE$13,C53=$BE$14,C53=$BE$15,C53=$BE$16,C53=$BE$17),IF(I53="Yes",1,0),"") | AX35: =IF(OR(C53=$BE$4,C53=$BE$5,C53=$BE$6,C53=$BE$7),IF(I53="Yes",1,0),"") | AY35: =IF(OR(C53=$BE$8),IF(I53="Yes",1,0),"") | AZ35: =IF(OR(C53=$BE$4,C53=$BE$5,C53=$BE$6,C53=$BE$7),IF(I53="Yes",1,0),"") | BA35: =IF(OR(C53=$BE$8),IF(I53="Yes",1,0),"") | BB35: =IF(OR(C53=$BE$9,C53=$BE$10,C53=$BE$11,C53=$BE$12,C53=$BE$13,C53=$BE$14,C53=$BE$15,C53=$BE$16,C53=$BE$17),IF(I53="Yes",1,0),"") | BC35: =AV35 -> - | BD35: =IF(OR(L64=$BE$4,L64=$BE$5,L64=$BE$8,L64=$BE$9,L64=$BE$10,L64=$BE$11,L64=$BE$12,L64=$BE$13,L64=$BE$14,L64=$BE$15,L64=$BE$16,L64=$BE$17),IF(W64="Yes",1,0),"") | BE35: =IF(OR(L64=$BE$4,L64=$BE$5,L64=$BE$6,L64=$BE$7),IF(W64="Yes",1,0),"") | BF35: =IF(OR(L64=$BE$8),IF(W64="Yes",1,0),"") | BG35: =IF(OR(L64=$BE$4,L64=$BE$5,L64=$BE$6,L64=$BE$7),IF(W64="Yes",1,0),"") | BH35: =IF(OR(L64=$BE$8),IF(W64="Yes",1,0),"") | BI35: =IF(OR(L64=$BE$9,L64=$BE$10,L64=$BE$11,L64=$BE$12,L64=$BE$13,L64=$BE$14,L64=$BE$15,L64=$BE$16,L64=$BE$17),IF(W64="Yes",1,0),"")
AO36: =$J28 | AP36: =$N28*$M28 -> 0 | AQ36: =VALUE(CONCATENATE(IF($G30="Ground",0,0),IF($G30=2,$D$13,0),IF($G30=3,2*$D$13,0),IF($G30=4,3*$D$13,0))) -> 0 | AS36: {=IFERROR(INDEX(AT$26:AT$54, MATCH(0, INDEX( COUNTIF( AS$25:AS35, AT$26:AT$54)+ (COUNTIF( AT$26:AT$54, AT$26:AT$54)<>1),), 0)),"")} -> Bedroom Seven | AT36: Bedroom Five | AU36: 0.015 | AV36: =C54 -> - | AW36: =IF(OR(C54=$BE$4,C54=$BE$5,C54=$BE$8,C54=$BE$9,C54=$BE$10,C54=$BE$11,C54=$BE$12,C54=$BE$13,C54=$BE$14,C54=$BE$15,C54=$BE$16,C54=$BE$17),IF(I54="Yes",1,0),"") | AX36: =IF(OR(C54=$BE$4,C54=$BE$5,C54=$BE$6,C54=$BE$7),IF(I54="Yes",1,0),"") | AY36: =IF(OR(C54=$BE$8),IF(I54="Yes",1,0),"") | AZ36: =IF(OR(C54=$BE$4,C54=$BE$5,C54=$BE$6,C54=$BE$7),IF(I54="Yes",1,0),"") | BA36: =IF(OR(C54=$BE$8),IF(I54="Yes",1,0),"") | BB36: =IF(OR(C54=$BE$9,C54=$BE$10,C54=$BE$11,C54=$BE$12,C54=$BE$13,C54=$BE$14,C54=$BE$15,C54=$BE$16,C54=$BE$17),IF(I54="Yes",1,0),"") | BC36: =AV36 -> - | BD36: =IF(OR(L66=$BE$4,L66=$BE$5,L66=$BE$8,L66=$BE$9,L66=$BE$10,L66=$BE$11,L66=$BE$12,L66=$BE$13,L66=$BE$14,L66=$BE$15,L66=$BE$16,L66=$BE$17),IF(W66="Yes",1,0),"") | BE36: =IF(OR(L66=$BE$4,L66=$BE$5,L66=$BE$6,L66=$BE$7),IF(W66="Yes",1,0),"") | BF36: =IF(OR(L66=$BE$8),IF(W66="Yes",1,0),"") | BG36: =IF(OR(L66=$BE$4,L66=$BE$5,L66=$BE$6,L66=$BE$7),IF(W66="Yes",1,0),"") | BH36: =IF(OR(L66=$BE$8),IF(W66="Yes",1,0),"") | BI36: =IF(OR(L66=$BE$9,L66=$BE$10,L66=$BE$11,L66=$BE$12,L66=$BE$13,L66=$BE$14,L66=$BE$15,L66=$BE$16,L66=$BE$17),IF(W66="Yes",1,0),"")
C37: Method One | L37: Method Two | AO37: =$J29 | AP37: =$N29*$M29 -> 0 | AQ37: =VALUE(CONCATENATE(IF($G31="Ground",0,0),IF($G31=2,$D$13,0),IF($G31=3,2*$D$13,0),IF($G31=4,3*$D$13,0))) -> 0 | AS37: {=IFERROR(INDEX(AT$26:AT$54, MATCH(0, INDEX( COUNTIF( AS$25:AS36, AT$26:AT$54)+ (COUNTIF( AT$26:AT$54, AT$26:AT$54)<>1),), 0)),"")} -> Bedroom Eight | AT37: Bedroom Six | AU37: 0.015 | AV37: =C55 -> - | AW37: =IF(OR(C55=$BE$4,C55=$BE$5,C55=$BE$8,C55=$BE$9,C55=$BE$10,C55=$BE$11,C55=$BE$12,C55=$BE$13,C55=$BE$14,C55=$BE$15,C55=$BE$16,C55=$BE$17),IF(I55="Yes",1,0),"") | AX37: =IF(OR(C55=$BE$4,C55=$BE$5,C55=$BE$6,C55=$BE$7),IF(I55="Yes",1,0),"") | AY37: =IF(OR(C55=$BE$8),IF(I55="Yes",1,0),"") | AZ37: =IF(OR(C55=$BE$4,C55=$BE$5,C55=$BE$6,C55=$BE$7),IF(I55="Yes",1,0),"") | BA37: =IF(OR(C55=$BE$8),IF(I55="Yes",1,0),"") | BB37: =IF(OR(C55=$BE$9,C55=$BE$10,C55=$BE$11,C55=$BE$12,C55=$BE$13,C55=$BE$14,C55=$BE$15,C55=$BE$16,C55=$BE$17),IF(I55="Yes",1,0),"") | BC37: =AV37 -> - | BD37: =IF(OR(L68=$BE$4,L68=$BE$5,L68=$BE$8,L68=$BE$9,L68=$BE$10,L68=$BE$11,L68=$BE$12,L68=$BE$13,L68=$BE$14,L68=$BE$15,L68=$BE$16,L68=$BE$17),IF(W68="Yes",1,0),"") | BE37: =IF(OR(L68=$BE$4,L68=$BE$5,L68=$BE$6,L68=$BE$7),IF(W68="Yes",1,0),"") | BF37: =IF(OR(L68=$BE$8),IF(W68="Yes",1,0),"") | BG37: =IF(OR(L68=$BE$4,L68=$BE$5,L68=$BE$6,L68=$BE$7),IF(W68="Yes",1,0),"") | BH37: =IF(OR(L68=$BE$8),IF(W68="Yes",1,0),"") | BI37: =IF(OR(L68=$BE$9,L68=$BE$10,L68=$BE$11,L68=$BE$12,L68=$BE$13,L68=$BE$14,L68=$BE$15,L68=$BE$16,L68=$BE$17),IF(W68="Yes",1,0),"")
AO38: =$J30 | AP38: =$N30*$M30 -> 0 | AQ38: =VALUE(CONCATENATE(IF($G32="Ground",0,0),IF($G32=2,$D$13,0),IF($G32=3,2*$D$13,0),IF($G32=4,3*$D$13,0))) -> 0 | AS38: {=IFERROR(INDEX(AT$26:AT$54, MATCH(0, INDEX( COUNTIF( AS$25:AS37, AT$26:AT$54)+ (COUNTIF( AT$26:AT$54, AT$26:AT$54)<>1),), 0)),"")} | AT38: Bedroom Seven | AU38: 0.015 | AV38: =C56 -> - | AW38: =IF(OR(C56=$BE$4,C56=$BE$5,C56=$BE$8,C56=$BE$9,C56=$BE$10,C56=$BE$11,C56=$BE$12,C56=$BE$13,C56=$BE$14,C56=$BE$15,C56=$BE$16,C56=$BE$17),IF(I56="Yes",1,0),"") | AX38: =IF(OR(C56=$BE$4,C56=$BE$5,C56=$BE$6,C56=$BE$7),IF(I56="Yes",1,0),"") | AY38: =IF(OR(C56=$BE$8),IF(I56="Yes",1,0),"") | AZ38: =IF(OR(C56=$BE$4,C56=$BE$5,C56=$BE$6,C56=$BE$7),IF(I56="Yes",1,0),"") | BA38: =IF(OR(C56=$BE$8),IF(I56="Yes",1,0),"") | BB38: =IF(OR(C56=$BE$9,C56=$BE$10,C56=$BE$11,C56=$BE$12,C56=$BE$13,C56=$BE$14,C56=$BE$15,C56=$BE$16,C56=$BE$17),IF(I56="Yes",1,0),"") | BC38: =AV38 -> - | BD38: =IF(OR(L70=$BE$4,L70=$BE$5,L70=$BE$8,L70=$BE$9,L70=$BE$10,L70=$BE$11,L70=$BE$12,L70=$BE$13,L70=$BE$14,L70=$BE$15,L70=$BE$16,L70=$BE$17),IF(W70="Yes",1,0),"") | BE38: =IF(OR(L70=$BE$4,L70=$BE$5,L70=$BE$6,L70=$BE$7),IF(W70="Yes",1,0),"") | BF38: =IF(OR(L70=$BE$8),IF(W70="Yes",1,0),"") | BG38: =IF(OR(L70=$BE$4,L70=$BE$5,L70=$BE$6,L70=$BE$7),IF(W70="Yes",1,0),"") | BH38: =IF(OR(L70=$BE$8),IF(W70="Yes",1,0),"") | BI38: =IF(OR(L70=$BE$9,L70=$BE$10,L70=$BE$11,L70=$BE$12,L70=$BE$13,L70=$BE$14,L70=$BE$15,L70=$BE$16,L70=$BE$17),IF(W70="Yes",1,0),"")
C39: Method One may only be used for Homestar levels 6 and 7. Use cells below to calculate whether windows in external walls are appropriately sized. | L39: Method Two may be used for all Homestar ratings, although it is required at 8-Star or higher | AO39: =$J31 | AP39: =$N31*$M31 -> 0 | AQ39: =VALUE(CONCATENATE(IF($G33="Ground",0,0),IF($G33=2,$D$13,0),IF($G33=3,2*$D$13,0),IF($G33=4,3*$D$13,0))) -> 0 | AS39: {=IFERROR(INDEX(AT$26:AT$54, MATCH(0, INDEX( COUNTIF( AS$25:AS38, AT$26:AT$54)+ (COUNTIF( AT$26:AT$54, AT$26:AT$54)<>1),), 0)),"")} | AT39: Bedroom Eight | AU39: 0.015 | AV39: =C57 -> - | AW39: =IF(OR(C57=$BE$4,C57=$BE$5,C57=$BE$8,C57=$BE$9,C57=$BE$10,C57=$BE$11,C57=$BE$12,C57=$BE$13,C57=$BE$14,C57=$BE$15,C57=$BE$16,C57=$BE$17),IF(I57="Yes",1,0),"") | AX39: =IF(OR(C57=$BE$4,C57=$BE$5,C57=$BE$6,C57=$BE$7),IF(I57="Yes",1,0),"") | AY39: =IF(OR(C57=$BE$8),IF(I57="Yes",1,0),"") | AZ39: =IF(OR(C57=$BE$4,C57=$BE$5,C57=$BE$6,C57=$BE$7),IF(I57="Yes",1,0),"") | BA39: =IF(OR(C57=$BE$8),IF(I57="Yes",1,0),"") | BB39: =IF(OR(C57=$BE$9,C57=$BE$10,C57=$BE$11,C57=$BE$12,C57=$BE$13,C57=$BE$14,C57=$BE$15,C57=$BE$16,C57=$BE$17),IF(I57="Yes",1,0),"") | BC39: =AV39 -> - | BD39: =IF(OR(L72=$BE$4,L72=$BE$5,L72=$BE$8,L72=$BE$9,L72=$BE$10,L72=$BE$11,L72=$BE$12,L72=$BE$13,L72=$BE$14,L72=$BE$15,L72=$BE$16,L72=$BE$17),IF(W72="Yes",1,0),"") | BE39: =IF(OR(L72=$BE$4,L72=$BE$5,L72=$BE$6,L72=$BE$7),IF(W72="Yes",1,0),"") | BF39: =IF(OR(L72=$BE$8),IF(W72="Yes",1,0),"") | BG39: =IF(OR(L72=$BE$4,L72=$BE$5,L72=$BE$6,L72=$BE$7),IF(W72="Yes",1,0),"") | BH39: =IF(OR(L72=$BE$8),IF(W72="Yes",1,0),"") | BI39: =IF(OR(L72=$BE$9,L72=$BE$10,L72=$BE$11,L72=$BE$12,L72=$BE$13,L72=$BE$14,L72=$BE$15,L72=$BE$16,L72=$BE$17),IF(W72="Yes",1,0),"")
AO40: =$J32 | AP40: =$N32*$M32 -> 0 | AQ40: =VALUE(CONCATENATE(IF($G34="Ground",0,0),IF($G34=2,$D$13,0),IF($G34=3,2*$D$13,0),IF($G34=4,3*$D$13,0))) -> 0 | AS40: {=IFERROR(INDEX(AT$26:AT$54, MATCH(0, INDEX( COUNTIF( AS$25:AS39, AT$26:AT$54)+ (COUNTIF( AT$26:AT$54, AT$26:AT$54)<>1),), 0)),"")} | AT40: =C20 -> Main Bedroom | AV40: =C58 -> - | AW40: =IF(OR(C58=$BE$4,C58=$BE$5,C58=$BE$8,C58=$BE$9,C58=$BE$10,C58=$BE$11,C58=$BE$12,C58=$BE$13,C58=$BE$14,C58=$BE$15,C58=$BE$16,C58=$BE$17),IF(I58="Yes",1,0),"") | AX40: =IF(OR(C58=$BE$4,C58=$BE$5,C58=$BE$6,C58=$BE$7),IF(I58="Yes",1,0),"") | AY40: =IF(OR(C58=$BE$8),IF(I58="Yes",1,0),"") | AZ40: =IF(OR(C58=$BE$4,C58=$BE$5,C58=$BE$6,C58=$BE$7),IF(I58="Yes",1,0),"") | BA40: =IF(OR(C58=$BE$8),IF(I58="Yes",1,0),"") | BB40: =IF(OR(C58=$BE$9,C58=$BE$10,C58=$BE$11,C58=$BE$12,C58=$BE$13,C58=$BE$14,C58=$BE$15,C58=$BE$16,C58=$BE$17),IF(I58="Yes",1,0),"") | BC40: =IF(K51="","",J51)
...

Sheet Materials Calculator
N1: =AG4 -> Concrete | O1: =AG5 -> Structural Timber | P1: =AG6 -> Other Timber (Except structural and cladding) | Q1: =AG7 -> Interior Engineered Wood | R1: =AG8 -> Other Engineered Wood | S1: =AG9 -> Interior Wall and Ceiling Linings | T1: =AG10 -> Wall Cladding | U1: =AG11 -> Roof Cladding | V1: =AG12 -> Floor Coverings | W1: =AG13 -> Applied Coatings | X1: =AG14 -> Structural Steel | Y1: =AG15 -> Insulation | AA1: =AG16 -> Adhesives and Sealants
B2: Materials Calculator | M2: Hide Everything to Right | N2: None | O2: None | P2: None | Q2: None | R2: None | S2: None | T2: None | U2: None | V2: None | W2: None | X2: None | Y2: None | AA2: Eco label
N3: Reused | O3: FSC/PEFC | P3: FSC/PEFC | Q3: Reused | R3: Reused | S3: Dematerialisation | T3: Reused | U3: Reused | V3: Dematerialisation | W3: Dematerialisation | X3: Eco Label Level A | Y3: Reused | AA3: IAQ scheme | AC3: Means of Compliance | AD3: Points | AF3: - | AG3: -
C4: Note: - For each construction system quantify material amounts in the given unit of measurement where practicable, otherwise a different unit can be used WITH NZGBC approval, BUT all items in a construction system must use the same measurement unit. | N4: Eco Label Level A | O4: ISO14001 | P4: ISO14001 | Q4: Eco Label Level A | R4: Eco Label Level A | S4: Reused | T4: Eco Label Level A | U4: Eco Label Level A | V4: Eco Label Level A | W4: Eco Label Level A | X4: Eco Label Level B | Y4: Eco Label Level A | AA4: Data sheet/testing report | AC4: Dematerialisation | AD4: 1.5 | AF4: 1 | AG4: Concrete | AH4: Tonnes/m3
N5: Recycled Content | O5: Enviromark Gold or above | P5: Enviromark Gold or above | Q5: Eco Label Level B | R5: Eco Label Level B | S5: Eco Label Level A | T5: Eco Label Level B | U5: Eco Label Level B | V5: Eco Label Level B | W5: Eco Label Level B | X5: Eco Label Level C | Y5: Eco Label Level B | AA5: Unglazed natural material | AC5: Reused | AD5: 1.5 | AF5: 2 | AG5: Structural Timber | AH5: Lineal Meters
N6: ISO14001 | O6: CarboNZero product certification | P6: CarboNZero product certification | Q6: Eco Label Level C | R6: Eco Label Level C | S6: Eco Label Level B | T6: Eco Label Level C | U6: Eco Label Level C | V6: Eco Label Level C | W6: Eco Label Level C | X6: ISO14001 | Y6: Eco Label Level C | AA6: Not compliant | AC6: Eco Label Level A | AD6: 1.5 | AF6: 3 | AG6: Other Timber (Except structural and cladding) | AH6: Lineal Meters
N7: Enviromark Gold or above | O7: Declare | P7: Declare | Q7: FSC/PEFC | R7: FSC/PEFC | S7: Eco Label Level C | T7: FSC/PEFC | U7: FSC/PEFC | V7: SMaRT Level A | W7: ISO14001 | X7: Enviromark Gold or above | Y7: FSC/PEFC | AC7: Eco Label Level B | AD7: 1 | AF7: 4 | AG7: Interior Engineered Wood | AH7: m2
C8: Total Points EN - 3 | F8: Total Points HC - 7 | N8: CarboNZero product certification | O8: CEMARS product certification | P8: CEMARS product certification | Q8: ISO14001 | R8: ISO14001 | S8: FSC/PEFC | T8: ISO14001 | U8: ISO14001 | V8: FSC/PEFC | W8: Enviromark Gold or above | X8: CarboNZero product certification | Y8: ISO14001 | AC8: Eco Label Level C | AD8: 0.75 | AF8: 5 | AG8: Other Engineered Wood | AH8: m2
C9: Sustainable Materials | D9: =MIN(SUM(D15:D28),10) -> 0 | F9: Healthy Materials | H9: =SUM(D69:D72) -> 0 | N9: Declare | O9: End-of-Life Stewardship Programme | P9: End-of-Life Stewardship Programme | Q9: Enviromark Gold or above | R9: Enviromark Gold or above | S9: ISO14001 | T9: Enviromark Gold or above | U9: Enviromark Gold or above | V9: ISO14001 | W9: CarboNZero product certification | X9: Declare | Y9: Enviromark Gold or above | AC9: FSC/PEFC | AD9: 1.5 | AF9: 6 | AG9: Interior Wall and Ceiling Linings | AH9: m2
N10: CEMARS product certification | O10: Reused | P10: Reused | Q10: CarboNZero product certification | R10: CarboNZero product certification | S10: Enviromark Gold or above | T10: CarboNZero product certification | U10: CarboNZero product certification | V10: Enviromark Gold or above | W10: Declare | X10: CEMARS product certification | Y10: CarboNZero product certification | AC10: ISO14001 | AD10: 0.75 | AG10: Wall Cladding | AH10: m2
N11: End-of-Life Stewardship Programme | O11: Product specific EPD | P11: Product specific EPD | Q11: Declare | R11: Declare | S11: CarboNZero product certification | T11: Declare | U11: Declare | V11: Recycled Content | W11: CEMARS product certification | X11: Recycled Content | Y11: Declare | AC11: Enviromark Gold or above | AD11: 0.25 | AF11: 8 | AG11: Roof Cladding | AH11: m2
C12: Summary of EN - 3 Sustainable Materials Points | N12: Product specific EPD | O12: Industry wide EPD | P12: Industry wide EPD | Q12: CEMARS product certification | R12: CEMARS product certification | S12: Declare | T12: CEMARS product certification | U12: CEMARS product certification | V12: CarboNZero product certification | W12: End-of-Life Stewardship Programme | X12: End-of-Life Stewardship Programme | Y12: CEMARS product certification | AC12: CarboNZero product certification | AD12: 0.75 | AF12: 9 | AG12: Floor Coverings | AH12: m2
N13: Industry wide EPD | Q13: End-of-Life Stewardship Programme | R13: End-of-Life Stewardship Programme | S13: CEMARS product certification | T13: End-of-Life Stewardship Programme | U13: End-of-Life Stewardship Programme | V13: Reused | W13: Product specific EPD | X13: Reused | Y13: End-of-Life Stewardship Programme | AC13: Declare | AD13: 0.25 | AF13: 10 | AG13: Applied Coatings | AH13: m2 or L
